Traceback (most recent call last):
  File "/Users/kkagawa/localdoc/github/Class/venv/lib/python3.13/site-packages/jupyter_core/utils/__init__.py", line 154, in wrapped
    asyncio.get_running_loop()
    ~~~~~~~~~~~~~~~~~~~~~~~~^^
RuntimeError: no running event loop

During handling of the above exception, another exception occurred:

Traceback (most recent call last):
  File "/Users/kkagawa/localdoc/github/Class/venv/lib/python3.13/site-packages/jupyter_cache/executors/utils.py", line 58, in single_nb_execution
    executenb(
    ~~~~~~~~~^
        nb,
        ^^^
    ...<4 lines>...
        **kwargs,
        ^^^^^^^^^
    )
    ^
  File "/Users/kkagawa/localdoc/github/Class/venv/lib/python3.13/site-packages/nbclient/client.py", line 1319, in execute
    return NotebookClient(nb=nb, resources=resources, km=km, **kwargs).execute()
           ~~~~~~~~~~~~~~~~~~~~~~~~~~~~~~~~~~~~~~~~~~~~~~~~~~~~~~~~~~~~~~~~~~~^^
  File "/Users/kkagawa/localdoc/github/Class/venv/lib/python3.13/site-packages/jupyter_core/utils/__init__.py", line 158, in wrapped
    return loop.run_until_complete(inner)
           ~~~~~~~~~~~~~~~~~~~~~~~^^^^^^^
  File "/opt/homebrew/Cellar/python@3.13/3.13.2/Frameworks/Python.framework/Versions/3.13/lib/python3.13/asyncio/base_events.py", line 725, in run_until_complete
    return future.result()
           ~~~~~~~~~~~~~^^
  File "/Users/kkagawa/localdoc/github/Class/venv/lib/python3.13/site-packages/nbclient/client.py", line 709, in async_execute
    await self.async_execute_cell(
        cell, index, execution_count=self.code_cells_executed + 1
    )
  File "/Users/kkagawa/localdoc/github/Class/venv/lib/python3.13/site-packages/nbclient/client.py", line 1062, in async_execute_cell
    await self._check_raise_for_error(cell, cell_index, exec_reply)
  File "/Users/kkagawa/localdoc/github/Class/venv/lib/python3.13/site-packages/nbclient/client.py", line 918, in _check_raise_for_error
    raise CellExecutionError.from_cell_and_msg(cell, exec_reply_content)
nbclient.exceptions.CellExecutionError: An error occurred while executing the following cell:
------------------
import numpy as np
import matplotlib.pyplot as plt
from matplotlib import rcParams

# ==== 日本語フォント設定 ====
# OSによって異なります。ここではIPAexゴシックを例示
# Windows: "MS Gothic" など
# macOS:   "Hiragino Sans" など
# rcParams['font.family'] = 'IPAexGothic'  # 適宜ご利用環境の日本語フォント名に変更してください
rcParams['font.family'] = 'Hiragino Sans'  # 適宜ご利用環境の日本語フォント名に変更してください

# ==== データ生成 ====
t = np.linspace(0, 4*np.pi, 500)      # 時間軸
analog = np.sin(t) + 1               # 振幅0〜2にするため +1
digital = np.where(analog >= 1, 2, 0) # 1以上なら2、1未満なら0

# ==== プロット ====
plt.figure(figsize=(10, 6))

# アナログ信号
plt.plot(t, analog, label='アナログ信号', color='blue')

# デジタル信号（階段状のステップとして表示）
plt.step(t, digital, where='mid', label='デジタル信号', color='red')

# 軸ラベル・タイトル
plt.xlabel('時間 [s]')
plt.ylabel('振幅')
plt.title('アナログ信号とデジタル信号の比較')

# グリッド・凡例
plt.grid(True)
plt.legend()

plt.show()

------------------


[31m---------------------------------------------------------------------------[39m
[31mModuleNotFoundError[39m                       Traceback (most recent call last)
[36mCell[39m[36m [39m[32mIn[1][39m[32m, line 1[39m
[32m----> [39m[32m1[39m [38;5;28;01mimport[39;00m[38;5;250m [39m[34;01mnumpy[39;00m[38;5;250m [39m[38;5;28;01mas[39;00m[38;5;250m [39m[34;01mnp[39;00m
[32m      2[39m [38;5;28;01mimport[39;00m[38;5;250m [39m[34;01mmatplotlib[39;00m[34;01m.[39;00m[34;01mpyplot[39;00m[38;5;250m [39m[38;5;28;01mas[39;00m[38;5;250m [39m[34;01mplt[39;00m
[32m      3[39m [38;5;28;01mfrom[39;00m[38;5;250m [39m[34;01mmatplotlib[39;00m[38;5;250m [39m[38;5;28;01mimport[39;00m rcParams

[31mModuleNotFoundError[39m: No module named 'numpy'

